# -*- coding: utf-8 -*-

from odoo import fields, models, api, _
from odoo.exceptions import UserError

class MusicArtist(models.Model):
    _name = 'oomusic.artist'
    _description = 'Music Artist'
    _order = 'name'

    name = fields.Char('Artist', index=True)
    track_ids = fields.One2many('oomusic.track', 'artist_id', string='Tracks')
    album_ids = fields.One2many('oomusic.album', 'artist_id', string='Albums')
    user_id = fields.Many2one(
        'res.users', string='User', index=True, required=True, ondelete='cascade',
        default=lambda self: self.env.user
    )

    _sql_constraints = [
        ('oomusic_artist_name_uniq', 'unique(name, user_id)', 'Artist name must be unique!'),
    ]

    @api.multi
    def action_add_to_playlist(self):
        Playlist = self.env['oomusic.playlist'].search([('current', '=', True)], limit=1)
        if not Playlist:
            raise UserError(_('No current playlist found!'))
        for artist in self:
            Playlist._add_tracks(artist.track_ids)
